Workbook

Sheet PORTADA
B2: PLAN DE GESTION DE RIESGOS
B3: Proyecto: SistemaVentas 360 — Implementacion de Sistema Integrado de Ventas e Inventario
B4: Metodologia: PMI PMBOK | Estandar: ISO 31000 | Version: 1.0
B6: Nombre del Proyecto | C6: SistemaVentas 360
B7: Tipo de Proyecto | C7: Desarrollo e Implementacion de Software ERP
B8: Cliente / Sponsor | C8: TecnoVentas S.A.
B9: Gerente de Proyecto | C9: [Nombre del PM]
B10: Version del Documento | C10: 1.0
B11: Fecha de Creacion | C11: [dd/mm/aaaa]
B12: Ultima Actualizacion | C12: [dd/mm/aaaa]
B13: Estado del Proyecto | C13: En ejecucion
B15: CONTENIDO DEL PLAN
B16: 1. PORTADA | C16: Datos del proyecto y resumen ejecutivo.
B17: 2. MARCO TEORICO | C17: Conceptos de gestion de riesgos, metodologia y escalas usadas.
B18: 3. REGISTRO DE RIESGOS | C18: Catalogo completo con 15 riesgos TI identificados, valorados y priorizados.
B19: 4. MATRIZ PROBABILIDAD | C19: Matriz de calor 5x5 con la ubicacion visual de cada riesgo.
B20: 5. PLAN DE RESPUESTA | C20: Estrategia, acciones y responsables para cada riesgo.
B21: 6. DASHBOARD CONTROL | C21: Semaforo de estado actual, KRI y resumen ejecutivo con graficos.
B22: 7. PLANTILLA EN BLANCO | C22: Plantilla editable para que los estudiantes documenten su propio proyecto.
B24: INSTRUCCION PARA ESTUDIANTES: Lee este plan de izquierda a derecha. Comienza con el Marco Teorico para entender los conceptos, luego estudia el Registro de Riesgos y el Plan de Respuesta. Finalmente usa la Plantilla en Blanco para construir el plan de tu propio proyecto informatico.

Sheet MARCO TEORICO
B2: MARCO TEORICO — Gestion de Riesgos en Proyectos TI
B3: Basado en PMBOK 6a Ed. (PMI) e ISO 31000:2018
B5: QUE ES LA GESTION DE RIESGOS
B6: Concepto | C6: Definicion | D6: Ejemplo Aplicado
B7: Riesgo | C7: Evento o condicion incierta que, si ocurre, tiene un efecto positivo o negativo en los objetivos del proyecto. | D7: Ejemplo: Un proveedor de software no entrega a tiempo puede retrasar el proyecto 3 semanas.
B8: Probabilidad | C8: Posibilidad de que el riesgo ocurra. Se mide en escala del 1 al 5 (Muy baja a Muy alta). | D8: Ejemplo: Probabilidad 4 (Alta) = existe evidencia de que ha ocurrido en proyectos similares.
B9: Impacto | C9: Magnitud del efecto si el riesgo ocurre. Se mide en escala del 1 al 5 (Muy bajo a Muy alto). | D9: Ejemplo: Impacto 5 (Muy alto) = el proyecto se cancela o el costo sube mas del 40%.
B10: Nivel de Riesgo | C10: Probabilidad x Impacto. Determina la prioridad de atencion. Puede ser CRITICO, ALTO, MEDIO o BAJO. | D10: Ejemplo: P=4 x I=4 = 16 = CRITICO. Requiere accion inmediata.
B11: Amenaza | C11: Riesgo con impacto NEGATIVO en el proyecto. Debe minimizarse o eliminarse. | D11: Ejemplo: Falla de seguridad que expone datos de clientes.
B12: Oportunidad | C12: Riesgo con impacto POSITIVO en el proyecto. Debe aprovecharse. | D12: Ejemplo: Nueva tecnologia que reduce el tiempo de desarrollo a la mitad.
B14: ESCALA DE PROBABILIDAD (1-5)
B15: Nivel | C15: Valor | D15: Criterio / Descripcion
B16: MUY BAJA | C16: 1 | D16: Muy improbable. Ocurre en menos del 10% de proyectos similares. Sin historial de ocurrencia.
B17: BAJA | C17: 2 | D17: Improbable. Ocurre entre 10% y 30%. Pocos antecedentes en proyectos similares.
B18: MEDIA | C18: 3 | D18: Posible. Ocurre entre 30% y 50%. Se ha visto en algunos proyectos del mismo tipo.
B19: ALTA | C19: 4 | D19: Probable. Ocurre entre 50% y 70%. Hay evidencia clara de ocurrencia en proyectos similares.
B20: MUY ALTA | C20: 5 | D20: Casi certeza. Ocurre en mas del 70%. Ha ocurrido en este tipo de proyectos anteriores.
B22: ESCALA DE IMPACTO (1-5)
B23: Nivel | C23: Valor | D23: Criterio / Descripcion
B24: MUY BAJO | C24: 1 | D24: Impacto insignificante. Retraso < 1 semana, costo adicional < 5%. No afecta entregables.
B25: BAJO | C25: 2 | D25: Impacto menor. Retraso 1-2 semanas, costo adicional 5-10%. Ajuste menor de alcance.
B26: MEDIO | C26: 3 | D26: Impacto moderado. Retraso 2-4 semanas, costo adicional 10-20%. Requiere aprobacion del sponsor.
B27: ALTO | C27: 4 | D27: Impacto significativo. Retraso 1-2 meses, costo adicional 20-40%. Cambio mayor en el proyecto.
B28: MUY ALTO | C28: 5 | D28: Impacto critico. Retraso > 2 meses, costo adicional > 40% o cancelacion del proyecto.
B30: CLASIFICACION DEL NIVEL DE RIESGO (NR = Probabilidad x Impacto)
B31: Rango NR | C31: Clasificacion | D31: Accion Requerida
B32: 1 – 4 | C32: BAJO | D32: Monitorear periodicamente. Accion solo si escala. Responsable: PM.
B33: 5 – 9 | C33: MEDIO | D33: Plan de contingencia preparado. Revision mensual. Responsable: PM + Area afectada.
B34: 10 – 14 | C34: ALTO | D34: Respuesta activa. Revision semanal. Escalar al Sponsor si no se controla.
B35: 15 – 25 | C35: CRITICO | D35: Accion INMEDIATA. Reunion de emergencia. Escalar al Comite de Proyecto.
B37: ESTRATEGIAS DE RESPUESTA A RIESGOS
B38: Estrategia | C38: Descripcion | D38: Cuando Usarla — Ejemplo TI
B39: EVITAR | C39: Eliminar la causa del riesgo cambiando el plan del proyecto. | D39: Cambiar la tecnologia de base de datos por una mas estable para evitar problemas de compatibilidad.
B40: TRANSFERIR | C40: Trasladar el impacto a un tercero (contrato, seguro, outsourcing). | D40: Contratar un proveedor de nube con SLA garantizado para que asuma el riesgo de disponibilidad del servidor.
B41: MITIGAR | C41: Reducir la probabilidad y/o el impacto del riesgo. | D41: Implementar revisiones de codigo (code review) semanales para reducir la probabilidad de bugs criticos.
B42: ACEPTAR | C42: Reconocer el riesgo y no tomar accion proactiva (activa o pasiva). | D42: Aceptar el riesgo de fluctuacion de precios de licencias menores. Solo documentar y reservar presupuesto.
B43: EXPLOTAR | C43: (Solo oportunidades) Asegurar que la oportunidad ocurra. | D43: Asignar al mejor desarrollador al modulo critico para maximizar la probabilidad de entrega anticipada.

Sheet REGISTRO DE RIESGOS
B2: REGISTRO DE RIESGOS — Proyecto SistemaVentas 360
B3: Proyecto: Implementacion de Sistema ERP de Ventas e Inventario | Total de Riesgos Identificados: 15
B5: COMO LEER ESTA TABLA: P = Probabilidad (1-5) | I = Impacto (1-5) | NR = P x I (Nivel de Riesgo) | CRITICO (15-25) = rojo oscuro | ALTO (10-14) = rojo claro | MEDIO (5-9) = amarillo | BAJO (1-4) = verde
B6: ID | C6: Categoria | D6: Descripcion del Riesgo | E6: Causa Raiz | F6: Consecuencia si Ocurre | G6: P | H6: I | I6: NR | J6: Nivel | K6: Tipo | L6: Estrategia | M6: Responsable | N6: Estado
B7: R-01 | C7: Tecnico | D7: Incompatibilidad entre el nuevo sistema ERP y los sistemas legados de inventario existentes. | E7: No se realizo analisis de compatibilidad previo al inicio del proyecto. | F7: Paralisis de la integracion. Retraso de 4-6 semanas y costo adicional estimado en $8M. | G7: 4 | H7: 5 | I7: =G7*H7 -> 20 | J7: CRITICO | K7: Amenaza | L7: Mitigar | M7: Arquitecto de Software | N7: Activo
B8: R-02 | C8: Proveedor | D8: El proveedor del modulo de pagos no entrega el API en el plazo acordado. | E8: Contrato sin penalidades por incumplimiento de hitos. | F8: Retraso en el modulo de ventas online. Impacto directo en la fecha de lanzamiento. | G8: 3 | H8: 4 | I8: =G8*H8 -> 12 | J8: ALTO | K8: Amenaza | L8: Transferir | M8: Gerente de Proyecto | N8: Activo
B9: R-03 | C9: Seguridad | D9: Vulnerabilidad de seguridad en el modulo de autenticacion de usuarios expone datos de clientes. | E9: Falta de pruebas de penetracion (pentest) durante el desarrollo. | F9: Filtro de datos de 50.000 clientes. Multas regulatorias y dano reputacional grave. | G9: 2 | H9: 5 | I9: =G9*H9 -> 10 | J9: ALTO | K9: Amenaza | L9: Mitigar | M9: Lider de Seguridad | N9: Activo
B10: R-04 | C10: Alcance | D10: Cambios continuos en los requerimientos por parte del cliente durante el desarrollo. | E10: Falta de un proceso formal de control de cambios (Change Management). | F10: Incremento del 30% en el alcance sin ajuste de presupuesto ni cronograma. | G10: 5 | H10: 4 | I10: =G10*H10 -> 20 | J10: CRITICO | K10: Amenaza | L10: Evitar | M10: Gerente de Proyecto | N10: Activo
B11: R-05 | C11: Recursos Humanos | D11: Renuncia de desarrolladores clave durante la fase critica de implementacion. | E11: Alta demanda de perfiles tecnicos en el mercado y falta de plan de retencion. | F11: Perdida de conocimiento critico. Retraso de 3-8 semanas en modulos asignados. | G11: 3 | H11: 5 | I11: =G11*H11 -> 15 | J11: CRITICO | K11: Amenaza | L11: Mitigar | M11: Gerente de RRHH | N11: Activo
B12: R-06 | C12: Calidad | D12: El sistema presenta errores criticos (bugs) en el modulo de facturacion al momento del go-live. | E12: Insuficientes pruebas de integracion y UAT antes del lanzamiento. | F12: Sistema inoperativo en produccion. Perdida de ventas durante el tiempo de correccion. | G12: 3 | H12: 5 | I12: =G12*H12 -> 15 | J12: CRITICO | K12: Amenaza | L12: Mitigar | M12: Lider QA | N12: Activo
B13: R-07 | C13: Tecnologico | D13: El servidor de produccion en la nube no soporta la carga de usuarios concurrentes esperada. | E13: Estimacion incorrecta de la carga de trabajo en la fase de arquitectura. | F13: Caidas del sistema en horas pico. Experiencia de usuario degradada y perdida de ventas. | G13: 3 | H13: 4 | I13: =G13*H13 -> 12 | J13: ALTO | K13: Amenaza | L13: Mitigar | M13: Arquitecto de Nube | N13: Activo
B14: R-08 | C14: Presupuesto | D14: El costo del proyecto supera el presupuesto aprobado en mas de un 25%. | E14: Estimaciones iniciales sin reservas de contingencia adecuadas. | F14: Cancelacion del proyecto o reduccion del alcance. Conflicto con el sponsor. | G14: 3 | H14: 4 | I14: =G14*H14 -> 12 | J14: ALTO | K14: Amenaza | L14: Mitigar | M14: Gerente de Proyecto | N14: Activo
B15: R-09 | C15: Integracion | D15: La migracion de datos historicos desde el sistema antiguo genera inconsistencias o perdida de datos. | E15: Sin plan formal de migracion ni validacion de calidad de datos en el sistema origen. | F15: Datos de clientes e historial de ventas incorrectos en el nuevo sistema. Impacto operacional. | G15: 4 | H15: 4 | I15: =G15*H15 -> 16 | J15: CRITICO | K15: Amenaza | L15: Mitigar | M15: Lider de Base de Datos | N15: Activo
B16: R-10 | C16: Usuarios Finales | D16: Los usuarios finales rechazan el nuevo sistema por falta de capacitacion y resistencia al cambio. | E16: Plan de gestion del cambio (Change Management) insuficiente o tardio. | F16: Baja adopcion del sistema. El negocio sigue usando procesos manuales en paralelo. | G16: 4 | H16: 3 | I16: =G16*H16 -> 12 | J16: ALTO | K16: Amenaza | L16: Mitigar | M16: Lider de Change Mgmt | N16: Activo
B17: R-11 | C17: Legal / Regulatorio | D17: El sistema no cumple con la normativa de proteccion de datos personales vigente. | E17: Falta de revision juridica del diseno del sistema durante la fase de analisis. | F17: Multas regulatorias, suspension del sistema y costo legal elevado. | G17: 2 | H17: 5 | I17: =G17*H17 -> 10 | J17: ALTO | K17: Amenaza | L17: Evitar | M17: Abogado de Proyecto | N17: Activo
B18: R-12 | C18: Comunicaciones | D18: Falta de comunicacion entre el equipo de desarrollo y el equipo de negocio genera malentendidos. | E18: No existe un protocolo formal de comunicacion ni reuniones de seguimiento regulares. | F18: Requerimientos mal interpretados que generan retrabajo y retrasos en entregas. | G18: 4 | H18: 3 | I18: =G18*H18 -> 12 | J18: ALTO | K18: Amenaza | L18: Mitigar | M18: Gerente de Proyecto | N18: Activo
... B21: R-15 | C21: Oportunidad | D21: El equipo de desarrollo adquiere experiencia en la nueva plataforma y puede reducir tiempos en futuros sprints. | E21: Curva de aprendizaje en nuevas tecnologias completada en los primeros 2 sprints. | F21: Velocidad del equipo aumenta un 20% a partir del Sprint 3. Entregas mas rapidas. | G21: 4 | H21: 3 | I21: =G21*H21 -> 12 | J21: ALTO | K21: Oportunidad | L21: Explotar | M21: Scrum Master | N21: Activo
B22: TOTALES / RESUMEN | G22: =AVERAGE(G7:G21) -> 3.2666667 | H22: =AVERAGE(H7:H21) -> 4.0666667 | I22: =AVERAGE(I7:I21) -> 13.066667 | J22: =COUNTIF(J7:J21,"CRITICO")&" C / "&COUNTIF(J7:J21,"ALTO")&" A / "&COUNTIF(J7:J21,"MEDIO")&" M / "&COUNTIF(J7:J21,"BAJO")&" B" -> 5 C / 9 A / 1 M / 0 B

Sheet MATRIZ P x I
B2: MATRIZ DE PROBABILIDAD vs IMPACTO — SistemaVentas 360
B3: Cada celda muestra los riesgos que caen en esa combinacion de Probabilidad (eje vertical) e Impacto (eje horizontal). Colores: VERDE=Bajo | AMARILLO=Medio | ROJO=Alto | ROJO OSCURO=Critico
B5: IMPACTO -> | C5: 1-MUY BAJO | D5: 2-BAJO | E5: 3-MEDIO | F5: 4-ALTO | G5: 5-MUY ALTO | J5: LEYENDA DE RIESGOS EN MATRIZ
B6: 5-MUY ALTA | C6: NR=5 — | D6: NR=10 — | E6: NR=15 — | F6: NR=20 R-04 | G6: NR=25 — | J6: R-01 (P=4, I=5, NR=20) | K6: Incompatibilidad entre el nuevo sistema ERP y los sistemas l...
B7: 4-ALTA | C7: NR=4 — | D7: NR=8 — | E7: NR=12 R-10 R-12 R-15 | F7: NR=16 R-09 | G7: NR=20 R-01 | J7: R-02 (P=3, I=4, NR=12) | K7: El proveedor del modulo de pagos no entrega el API en el pla...
B8: 3-MEDIA | C8: NR=3 — | D8: NR=6 — | E8: NR=9 — | F8: NR=12 R-02 R-07 R-08 R-14 | G8: NR=15 R-05 R-06 | J8: R-03 (P=2, I=5, NR=10) | K8: Vulnerabilidad de seguridad en el modulo de autenticacion de...
B9: 2-BAJA | C9: NR=2 — | D9: NR=4 — | E9: NR=6 R-13 | F9: NR=8 — | G9: NR=10 R-03 R-11 | J9: R-04 (P=5, I=4, NR=20) | K9: Cambios continuos en los requerimientos por parte del client...
B10: 1-MUY BAJA | C10: NR=1 — | D10: NR=2 — | E10: NR=3 — | F10: NR=4 — | G10: NR=5 — | J10: R-05 (P=3, I=5, NR=15) | K10: Renuncia de desarrolladores clave durante la fase critica de...
J11: R-06 (P=3, I=5, NR=15) | K11: El sistema presenta errores criticos (bugs) en el modulo de ...
J12: R-07 (P=3, I=4, NR=12) | K12: El servidor de produccion en la nube no soporta la carga de ...
J13: R-08 (P=3, I=4, NR=12) | K13: El costo del proyecto supera el presupuesto aprobado en mas ...
J14: R-09 (P=4, I=4, NR=16) | K14: La migracion de datos historicos desde el sistema antiguo ge...
J15: R-10 (P=4, I=3, NR=12) | K15: Los usuarios finales rechazan el nuevo sistema por falta de ...
J16: R-11 (P=2, I=5, NR=10) | K16: El sistema no cumple con la normativa de proteccion de datos...
J17: R-12 (P=4, I=3, NR=12) | K17: Falta de comunicacion entre el equipo de desarrollo y el equ...
J18: R-13 (P=2, I=3, NR=6) | K18: La tecnologia elegida (framework) queda obsoleta o sin sopor...
J19: R-14 (P=3, I=4, NR=12) | K19: Una nueva API de integracion del proveedor permite reducir e...
J20: R-15 (P=4, I=3, NR=12) | K20: El equipo de desarrollo adquiere experiencia en la nueva pla...

Sheet PLAN DE RESPUESTA
B2: PLAN DE RESPUESTA A RIESGOS — SistemaVentas 360
B3: Para cada riesgo se define: acciones preventivas (antes de que ocurra) y correctivas (si ya ocurrio), propietario y fecha limite.
B5: ID | C5: Nivel | D5: Accion Preventiva (Antes que ocurra) | E5: Accion Correctiva / Contingencia (Si ocurre) | F5: Propietario | G5: Fecha Limite | H5: Presupuesto Estimado | I5: KRI — Indicador de Alerta
B6: R-01 | C6: CRITICO | D6: Realizar un analisis de compatibilidad tecnica completo en las primeras 2 semanas. Desarrollar capa de integracion (middleware) como buffer entre sistemas. | E6: Activar plan de desarrollo de adaptadores de integracion. Asignar 2 desarrolladores adicionales. Informar al sponsor sobre el retraso estimado. | F6: Arquitecto de Software | G6: Semana 2 | H6: $3.500.000 | I6: % de pruebas de integracion exitosas < 80% en semana 3
B7: R-02 | C7: ALTO | D7: Incluir penalidades por incumplimiento en el contrato con el proveedor. Identificar proveedor alternativo como respaldo. | E7: Activar al proveedor de respaldo. Escalar al area legal para aplicar penalidades contractuales. Ajustar cronograma. | F7: Gerente de Proyecto | G7: Semana 1 | H7: $500.000 | I7: Hito de entrega del API con retraso > 3 dias habiles
B8: R-03 | C8: CRITICO | D8: Contratar servicio de pentest antes del go-live. Implementar OWASP Top 10 como checklist obligatorio de desarrollo. Cifrar todos los datos sensibles. | E8: Aislar el modulo afectado. Notificar a usuarios segun normativa. Activar equipo de respuesta a incidentes. Contratar auditoria externa. | F8: Lider de Seguridad | G8: Sprint 3 | H8: $4.200.000 | I8: Hallazgo de vulnerabilidad critica en revision de codigo o pentest
B9: R-04 | C9: CRITICO | D9: Implementar proceso formal de Control de Cambios con formulario de solicitud. Congelar requerimientos al inicio de cada sprint. | E9: Evaluar impacto del cambio en cronograma y costo. Presentar al sponsor para aprobacion formal. Renegociar alcance si es necesario. | F9: Gerente de Proyecto | G9: Semana 1 | H9: $200.000 | I9: Mas de 2 solicitudes de cambio de alcance en una semana
B10: R-05 | C10: CRITICO | D10: Documentar el conocimiento de roles clave (knowledge transfer). Establecer bono de retencion para los 3 desarrolladores criticos. | E10: Activar proceso de busqueda urgente. Asignar mentor interno. Evaluar contratar consultora para cubrir el rol temporalmente. | F10: Gerente de RRHH | G10: Semana 2 | H10: $6.000.000 | I10: Recepcion de carta de renuncia de cualquier recurso en ruta critica
B11: R-06 | C11: CRITICO | D11: Definir plan de pruebas formal (unit, integration, UAT) con criterios de aceptacion claros. Requiere 2 semanas de UAT con usuarios reales. | E11: Revertir al sistema anterior (rollback). Comunicar a usuarios. Corregir bugs criticos en modo emergencia. Nuevo go-live tras validacion. | F11: Lider QA | G11: 2 semanas antes del go-live | H11: $1.800.000 | I11: Tasa de defectos criticos > 0 en UAT a 5 dias del go-live
B12: R-07 | C12: ALTO | D12: Realizar pruebas de carga (load testing) con 150% de la carga esperada. Configurar auto-scaling en la nube. | E12: Escalar recursos del servidor de inmediato. Activar CDN y cache. Habilitar modo de mantenimiento si la caida supera el 30% de usuarios. | F12: Arquitecto de Nube | G12: 1 semana antes del go-live | H12: $2.500.000 | I12: Tiempo de respuesta del servidor > 3 segundos en prueba de carga
B13: R-08 | C13: ALTO | D13: Incluir reserva de contingencia del 15% en el presupuesto. Revisar costos quincenalmente con el sponsor. | E13: Revisar alcance para reducir entregables. Renegociar contratos. Presentar opciones al sponsor: mas presupuesto o menos alcance. | F13: Gerente de Proyecto | G13: Mensual | H13: Sin costo adicional | I13: Gasto acumulado supera el 90% del presupuesto a mitad del proyecto
B14: R-09 | C14: ALTO | D14: Levantar inventario completo de datos origen. Crear scripts de validacion de calidad antes de migrar. Migracion en ambiente de prueba primero. | E14: Detener la migracion. Revisar y limpiar datos origen. Volver a ejecutar migracion con datos corregidos. Validar con usuarios. | F14: Lider de Base de Datos | G14: 2 semanas antes del go-live | H14: $1.200.000 | I14: Tasa de inconsistencia de datos en ambiente de prueba > 1%
B15: R-10 | C15: MEDIO | D15: Iniciar plan de capacitacion 4 semanas antes del go-live. Designar champions de cambio en cada area. | E15: Extender el periodo de capacitacion. Activar soporte presencial post go-live por 2 semanas. Crear material de ayuda rapida. | F15: Lider de Change Mgmt | G15: 4 semanas antes del go-live | H15: $2.800.000 | I15: Asistencia a capacitaciones < 70% o encuesta de adopcion < 60%
B16: R-11 | C16: CRITICO | D16: Contratar revision juridica del diseno del sistema en la fase de analisis. Implementar modulo de consentimiento de datos. | E16: Suspender el modulo no conforme. Contratar consultoria legal urgente. Ajustar el sistema. Notificar a la autoridad regulatoria. | F16: Abogado de Proyecto | G16: Fase de Diseno | H16: $3.000.000 | I16: Hallazgo de incumplimiento en auditoria interna de compliance
... B20: R-15 | C20: OPO. | D20: Reconocer y documentar el aumento de velocidad del equipo. Actualizar el plan de sprints para capitalizar el incremento. | E20: No aplica (oportunidad). Mantener el plan original si la mejora no se materializa. | F20: Scrum Master | G20: Sprint 3 | H20: $0 (sin costo) | I20: Velocidad del equipo no aumenta en Sprint 3 respecto a Sprint 1

Sheet DASHBOARD CONTROL
B2: DASHBOARD DE CONTROL DE RIESGOS — SistemaVentas 360
B3: Semana de Reporte: [Completar] | Elaborado por: [PM] | Proxima revision: [Fecha]
B5: RESUMEN EJECUTIVO DEL PLAN
B6: Total Riesgos | C6: Criticos | D6: Altos | E6: Medios | F6: Bajos | G6: Oportunidades | H6: Amenazas
B7: =COUNTA('REGISTRO DE RIESGOS'!B7:B21) -> 15 | C7: =COUNTIF('REGISTRO DE RIESGOS'!J7:J21,"CRITICO") -> 5 | D7: =COUNTIF('REGISTRO DE RIESGOS'!J7:J21,"ALTO") -> 9 | E7: =COUNTIF('REGISTRO DE RIESGOS'!J7:J21,"MEDIO") -> 1 | F7: =COUNTIF('REGISTRO DE RIESGOS'!J7:J21,"BAJO") -> 0 | G7: =COUNTIF('REGISTRO DE RIESGOS'!K7:K21,"Oportunidad") -> 2 | H7: =COUNTIF('REGISTRO DE RIESGOS'!K7:K21,"Amenaza") -> 13
B9: SEMAFORO DE ESTADO DE RIESGOS CRITICOS Y ALTOS
B10: ID | C10: Nivel NR | D10: Estado Actual | E10: Tendencia | F10: Ultimo Evento | G10: Proxima Accion | H10: Semaforo
B11: R-01 | C11: CRITICO (NR=20) | D11: Analisis de compatibilidad 60% completo. | E11: → Estable | F11: Prueba de integracion con BD legada exitosa al 70%. | G11: Completar analisis. Resultado en semana 3. | H11: PRECAUCION
B12: R-02 | C12: ALTO (NR=12) | D12: Contrato revisado con penalidades incluidas. | E12: ↑ Mejorando | F12: Proveedor confirmo fecha de entrega API. | G12: Monitorear hito de entrega del API en 5 dias. | H12: BIEN
B13: R-03 | C13: CRITICO (NR=10) | D13: Pentest contratado. Inicia en sprint 3. | E13: → Estable | F13: Checklist OWASP implementado en el 80% del codigo. | G13: Completar pentest antes del sprint 4. | H13: PRECAUCION
B14: R-04 | C14: CRITICO (NR=20) | D14: Control de cambios activo desde semana 1. | E14: ↑ Mejorando | F14: 2 solicitudes de cambio rechazadas formalmente. | G14: Capacitar al equipo en el proceso de cambio. | H14: BIEN
B15: R-05 | C15: CRITICO (NR=15) | D15: Bono de retencion firmado por 2 de 3 devs. | E15: → Estable | F15: 1 desarrollador aun no ha firmado el bono. | G15: Negociar con el desarrollador pendiente esta semana. | H15: PRECAUCION
B16: R-06 | C16: CRITICO (NR=15) | D16: Plan de pruebas aprobado por QA y negocio. | E16: ↑ Mejorando | F16: UAT planificada para 2 semanas antes del go-live. | G16: Preparar ambiente de UAT con datos reales. | H16: BIEN
B17: R-07 | C17: ALTO (NR=12) | D17: Load testing programado para semana 8. | E17: → Estable | F17: Auto-scaling configurado en el servidor de nube. | G17: Ejecutar primera ronda de load testing. | H17: PRECAUCION
B18: R-09 | C18: ALTO (NR=16) | D18: Scripts de validacion de datos en desarrollo. | E18: ↓ En riesgo | F18: Datos origen tienen 3% de inconsistencias detectadas. | G18: URGENTE: Limpiar datos origen antes del sprint 5. | H18: ALERTA
B19: R-11 | C19: CRITICO (NR=10) | D19: Revision juridica iniciada con consultora. | E19: → Estable | F19: Identificadas 2 areas de mejora en el diseno. | G19: Implementar cambios de compliance en sprint 4. | H19: PRECAUCION
B22: DISTRIBUCION DE RIESGOS POR NIVEL
B23: Nivel | C23: Cantidad
B24: CRITICO | C24: 6
B25: ALTO | C25: 4
B26: MEDIO | C26: 3
B27: BAJO | C27: 2

Sheet PLANTILLA ALUMNOS
B2: PLANTILLA PLAN DE GESTION DE RIESGOS — [Nombre de tu Proyecto]
B3: INSTRUCCION: Completa cada seccion con los datos de tu proyecto informatico. Sigue el orden: 1) Datos del proyecto → 2) Identificar riesgos → 3) Valorar P e I → 4) Definir estrategia → 5) Plan de respuesta. Borra los textos en gris y escribe tus respuestas reales.
B5: DATOS DEL PROYECTO
B6: Nombre del Proyecto | C6: Aplicación de Traducción de Frases Médicas
B7: Objetivo del Proyecto | C7: Facilitar la comunicación entre el personal médico y los pacientes mediante un sistema de traducción de frases críticas de salud.
B8: Sponsor / Cliente | C8: Centro de Salud (CESFAM) / Hospitales
B9: Gerente de Proyecto | C9: Ariel Valverde
B10: Fecha de Inicio | C10: Agosto 2026
B11: Fecha de Termino Estimada | C11: Noviembre 2026
B12: Presupuesto Total | C12: Presupuesto Académico (Proyecto de Título Capstone)
B13: Equipo de Proyecto (roles) | C13: Desarrollador, Scrum Master, Product Owner, Diseñador UX/UI, Analista de Procesos, Arquitecto de Software
B15: REGISTRO DE RIESGOS — Completa al menos 8 riesgos de tu proyecto
B16: P = Probabilidad (1 a 5) | I = Impacto (1 a 5) | NR = P x I | Nivel: BAJO (1-4) / MEDIO (5-9) / ALTO (10-14) / CRITICO (15-25) | Estrategia: Evitar / Transferir / Mitigar / Aceptar / Explotar
B17: ID | C17: Categoria | D17: Descripcion del Riesgo | E17: Causa Raiz | F17: Consecuencia si Ocurre | G17: P | H17: I | I17: NR | J17: Nivel | K17: Tipo | L17: Estrategia | M17: Responsable | N17: Estado
B18: R-01 | C18: Técnico | D18: Caída o mala configuración del servidor de alojamiento. | E18: Errores en la configuración o fallas del proveedor en la nube. | F18: Inaccesibilidad a la aplicación y bases de datos, afectando el desarrollo. | G18: 2 | H18: 4 | I18: 8 | J18: MEDIO | K18: Amenaza | L18: Mitigar | M18: Arquitecto de Software | N18: Activo
B19: R-02 | C19: Negocio / Requisitos | D19: Las 20 a 30 frases médicas iniciales no cubren las necesidades críticas. | E19: Falta de validación profunda con el personal médico de urgencia. | F19: Baja adopción de la aplicación en el CESFAM y problemas de comunicación. | G19: 1 | H19: 5 | I19: 5 | J19: MEDIO | K19: Amenaza | L19: Evitar | M19: Product Owner | N19: Activo
B20: R-03 | C20: Diseño UX/UI | D20: Incompatibilidad o mala usabilidad del diseño en dispositivos de pacientes. | E20: Uso de diseños complejos o incompatibles con dispositivos de gama baja. | F20: Usuarios finales no podrán utilizar el módulo de traducción correctamente. | G20: 3 | H20: 3 | I20: 9 | J20: MEDIO | K20: Amenaza | L20: Mitigar | M20: Diseñador UX/UI | N20: Activo
B21: R-04 | C21: Planificación | D21: Retraso en el desarrollo del módulo principal de traducción. | E21: Subestimación del tiempo necesario para codificar la interfaz y la BD. | F21: Incumplimiento de la fecha de término del Sprint o proyecto general. | G21: 3 | H21: 4 | I21: 12 | J21: ALTO | K21: Amenaza | L21: Mitigar | M21: Desarrollador / Scrum Master | N21: Activo
B22: R-05 | C22: Técnico | D22: Pérdida de código o conflictos graves en el repositorio de GitHub. | E22: Mala gestión de ramas (branching) o configuración incorrecta de accesos. | F22: Pérdida de funcionalidades, necesidad de retrabajo y bloqueos del equipo. | G22: 2 | H22: 4 | I22: 8 | J22: MEDIO | K22: Amenaza | L22: Mitigar | M22: Desarrollador | N22: Activo
B23: R-06 | C23: Calidad | D23: El diagrama de procesos no refleja el flujo real de atención médica. | E23: Falta de levantamiento de información o no validación con stakeholders. | F23: Desarrollo de un sistema desalineado con la realidad del recinto de salud. | G23: 2 | H23: 5 | I23: 10 | J23: ALTO | K23: Amenaza | L23: Evitar | M23: Analista de Procesos | N23: Activo
B24: R-07 | C24: Seguridad | D24: Accesos no autorizados a la base de datos o servidor. | E24: Configuración deficiente de seguridad y accesos remotos. | F24: Posible vulneración de datos del proyecto y configuraciones del servidor. | G24: 2 | H24: 5 | I24: 10 | J24: ALTO | K24: Amenaza | L24: Evitar | M24: Arquitecto de Software | N24: Activo
B25: R-08 | C25: Comunicación | D25: Problemas de comunicación y coordinación en el equipo ágil. | E25: Falta de reuniones de seguimiento o no uso de la herramienta de backlog. | F25: Bloqueos entre tareas dependientes y desalineación de los entregables. | G25: 3 | H25: 3 | I25: 9 | J25: MEDIO | K25: Amenaza | L25: Mitigar | M25: Scrum Master | N25: Activo
B26: R-09
B27: R-10
B28: R-11
B29: R-12
B31: PLAN DE RESPUESTA — Una fila por cada riesgo identificado
B32: ID | C32: Nivel | D32: Accion Preventiva (antes que ocurra) | E32: Accion Correctiva / Contingencia (si ya ocurrio) | F32: Propietario | G32: Fecha Limite | H32: Costo Estimado | I32: KRI — Indicador de Alerta
B33: R-01 | C33: CRÍTICO | D33: Realizar diagnóstico técnico exhaustivo de los sistemas legados antes de diseñar la arquitectura. | E33: Desarrollar una capa de integración intermedia (middleware) para aislar incompatibilidades. | F33: Arquitecto de Software | G33: Mes 2 | H33: 3500 | I33: % de APIs de sistemas legados sin documentación > 15%
B34: R-02 | C34: CRÍTICO | D34: Levantar el estado de la red y exigir mejora de ancho de banda (mín. 20 Mbps). | E34: Habilitar un modo "offline" básico o reducir la transmisión de datos gráficos pesados. | F34: Arquitecto de Software | G34: Mes 3 | H34: 2500 | I34: Velocidad de red en nodos críticos < 20 Mbps detectada
B35: R-03 | C35: CRÍTICO | D35: Crear scripts de limpieza y migrar los datos en un ambiente de pruebas primero. | E35: Detener la migración, limpiar base de origen y reiniciar proceso con datos corregidos. | F35: Analista de Datos | G35: Mes 6 | H35: 1500 | I35: Tasa de inconsistencia en ambiente de prueba > 2%
B36: R-04 | C36: CRÍTICO | D36: Implementar pruebas de penetración (pentest) y cifrar datos médicos sensibles. | E36: Aislar el módulo, activar plan de respuesta a incidentes y notificar según Ley 19.628. | F36: Especialista en Ciberseguridad | G36: Mes 8 | H36: 4000 | I36: Hallazgo de vulnerabilidad en revisión de código o pentest
B37: R-05 | C37: ALTO | D37: Plan de gestión del cambio temprano y diseñar una UI/UX muy intuitiva. | E37: Extender marcha blanca con soporte técnico presencial en los hospitales. | F37: Especialista UX | G37: Mes 9 | H37: 2000 | I37: Asistencia a capacitaciones del personal médico < 70%
B38: R-06 | C38: ALTO | D38: Estimar usando método PERT y aplicar control de cambios estricto al alcance. | E38: Reducir el alcance de entregables no críticos y reasignar horas extra al equipo. | F38: Gerente de Proyecto | G38: Mensual | H38: 5000 | I38: Atraso acumulado en la ruta crítica > 1 semana
B39: R-07 | C39: MEDIO | D39: Mantener comunicación activa y reportes de estado transparentes con Minsal y Hospital. | E39: Activar plan de contingencia comunicacional explicando las razones de los desvíos. | F39: Gerente de Proyecto | G39: Mensual | H39: 0 | I39: Incremento de quejas institucionales formales > 0
B40: R-08 | C40: ALTO | D40: Pruebas de estrés y carga (load testing) simulando 12.000 usuarios concurrentes. | E40: Escalar servidores temporalmente y habilitar caché/CDN de emergencia. | F40: Ingenieros Testing (QA) | G40: Mes 8 | H40: 3000 | I40: Tiempo de respuesta del servidor > 3 segundos bajo estrés
B41: R-09 | C41: MEDIO | D41: (Explotar) Asignar al equipo tareas complejas tempranas para acelerar su aprendizaje. | E41: (Si ocurre) Ajustar cronograma para adelantar la fecha de entregas (ahorro de tiempo). | F41: Gerente de Proyecto | G41: Sprint 3 | H41: 0 | I41: Velocidad del equipo aumenta un 20% antes del Sprint 3
B42: R-10
B43: R-11
B44: R-12
...
